Workbook
Name All_Teams: OFFSET(Games!#REF!,0,0,COUNTA(Games!#REF!)-1,1)
Name Method: Games!#REF!
Name SeedInfo: Games!#REF!
Name SeedType: Games!#REF!
Name snowball: [1]Calculator!$F$21
Name strategy: [1]Calculator!$F$20
Name valuevx: 42.314159

Sheet Team_Links
A1: Column1 | B1: School | C1: Link | D1: GameLogs | E1: PartialLink
A2: 0 | B2: Abilene Christian | C2: https://www.sports-reference.com/cbb/schools/abilene-christian/men/2026.html | D2: https://www.sports-reference.com/cbb/schools/abilene-christian/men/2026-gamelogs.html | E2: {=_xlfn.TEXTSPLIT( _xlfn.TEXTSPLIT(Team_Links[[#This Row],[GameLogs]],"https://www.sports-reference.com/cbb/schools/",,TRUE,0,), "/",,TRUE,0)} -> abilene-christian
A3: 1 | B3: Air Force | C3: https://www.sports-reference.com/cbb/schools/air-force/men/2026.html | D3: https://www.sports-reference.com/cbb/schools/air-force/men/2026-gamelogs.html | E3: {=_xlfn.TEXTSPLIT( _xlfn.TEXTSPLIT(Team_Links[[#This Row],[GameLogs]],"https://www.sports-reference.com/cbb/schools/",,TRUE,0,), "/",,TRUE,0)} -> air-force
A4: 2 | B4: Akron | C4: https://www.sports-reference.com/cbb/schools/akron/men/2026.html | D4: https://www.sports-reference.com/cbb/schools/akron/men/2026-gamelogs.html | E4: {=_xlfn.TEXTSPLIT( _xlfn.TEXTSPLIT(Team_Links[[#This Row],[GameLogs]],"https://www.sports-reference.com/cbb/schools/",,TRUE,0,), "/",,TRUE,0)} -> akron
A5: 3 | B5: Alabama | C5: https://www.sports-reference.com/cbb/schools/alabama/men/2026.html | D5: https://www.sports-reference.com/cbb/schools/alabama/men/2026-gamelogs.html | E5: {=_xlfn.TEXTSPLIT( _xlfn.TEXTSPLIT(Team_Links[[#This Row],[GameLogs]],"https://www.sports-reference.com/cbb/schools/",,TRUE,0,), "/",,TRUE,0)} -> alabama
A6: 4 | B6: Alabama A&M | C6: https://www.sports-reference.com/cbb/schools/alabama-am/men/2026.html | D6: https://www.sports-reference.com/cbb/schools/alabama-am/men/2026-gamelogs.html | E6: {=_xlfn.TEXTSPLIT( _xlfn.TEXTSPLIT(Team_Links[[#This Row],[GameLogs]],"https://www.sports-reference.com/cbb/schools/",,TRUE,0,), "/",,TRUE,0)} -> alabama-am
A7: 5 | B7: Alabama State | C7: https://www.sports-reference.com/cbb/schools/alabama-state/men/2026.html | D7: https://www.sports-reference.com/cbb/schools/alabama-state/men/2026-gamelogs.html | E7: {=_xlfn.TEXTSPLIT( _xlfn.TEXTSPLIT(Team_Links[[#This Row],[GameLogs]],"https://www.sports-reference.com/cbb/schools/",,TRUE,0,), "/",,TRUE,0)} -> alabama-state
A8: 6 | B8: Albany (NY) | C8: https://www.sports-reference.com/cbb/schools/albany-ny/men/2026.html | D8: https://www.sports-reference.com/cbb/schools/albany-ny/men/2026-gamelogs.html | E8: {=_xlfn.TEXTSPLIT( _xlfn.TEXTSPLIT(Team_Links[[#This Row],[GameLogs]],"https://www.sports-reference.com/cbb/schools/",,TRUE,0,), "/",,TRUE,0)} -> albany-ny
A9: 7 | B9: Alcorn State | C9: https://www.sports-reference.com/cbb/schools/alcorn-state/men/2026.html | D9: https://www.sports-reference.com/cbb/schools/alcorn-state/men/2026-gamelogs.html | E9: {=_xlfn.TEXTSPLIT( _xlfn.TEXTSPLIT(Team_Links[[#This Row],[GameLogs]],"https://www.sports-reference.com/cbb/schools/",,TRUE,0,), "/",,TRUE,0)} -> alcorn-state
A10: 8 | B10: American | C10: https://www.sports-reference.com/cbb/schools/american/men/2026.html | D10: https://www.sports-reference.com/cbb/schools/american/men/2026-gamelogs.html | E10: {=_xlfn.TEXTSPLIT( _xlfn.TEXTSPLIT(Team_Links[[#This Row],[GameLogs]],"https://www.sports-reference.com/cbb/schools/",,TRUE,0,), "/",,TRUE,0)} -> american
A11: 9 | B11: Appalachian State | C11: https://www.sports-reference.com/cbb/schools/appalachian-state/men/2026.html | D11: https://www.sports-reference.com/cbb/schools/appalachian-state/men/2026-gamelogs.html | E11: {=_xlfn.TEXTSPLIT( _xlfn.TEXTSPLIT(Team_Links[[#This Row],[GameLogs]],"https://www.sports-reference.com/cbb/schools/",,TRUE,0,), "/",,TRUE,0)} -> appalachian-state
A12: 10 | B12: Arizona | C12: https://www.sports-reference.com/cbb/schools/arizona/men/2026.html | D12: https://www.sports-reference.com/cbb/schools/arizona/men/2026-gamelogs.html | E12: {=_xlfn.TEXTSPLIT( _xlfn.TEXTSPLIT(Team_Links[[#This Row],[GameLogs]],"https://www.sports-reference.com/cbb/schools/",,TRUE,0,), "/",,TRUE,0)} -> arizona
A13: 11 | B13: Arizona State | C13: https://www.sports-reference.com/cbb/schools/arizona-state/men/2026.html | D13: https://www.sports-reference.com/cbb/schools/arizona-state/men/2026-gamelogs.html | E13: {=_xlfn.TEXTSPLIT( _xlfn.TEXTSPLIT(Team_Links[[#This Row],[GameLogs]],"https://www.sports-reference.com/cbb/schools/",,TRUE,0,), "/",,TRUE,0)} -> arizona-state
... A366: 364 | B366: Youngstown State | C366: https://www.sports-reference.com/cbb/schools/youngstown-state/men/2026.html | D366: https://www.sports-reference.com/cbb/schools/youngstown-state/men/2026-gamelogs.html | E366: {=_xlfn.TEXTSPLIT( _xlfn.TEXTSPLIT(Team_Links[[#This Row],[GameLogs]],"https://www.sports-reference.com/cbb/schools/",,TRUE,0,), "/",,TRUE,0)} -> youngstown-state

Sheet 2024 Roster (Wikipedia)
A1: East | I1: West | Q1: South | Y1: Midwest
A2: Seed | B2: School | C2: Conference | D2: Record | E2: Overall Seed | F2: Berth type | G2: Last bid | I2: Seed | J2: School | K2: Conference | L2: Record | M2: Overall Seed | N2: Berth type | O2: Last bid | Q2: Seed | R2: School | S2: Conference | T2: Record | U2: Overall Seed | V2: Berth type | W2: Last bid | Y2: Seed | Z2: School | AA2: Conference | AB2: Record | AC2: Overall Seed | AD2: Berth type | AE2: Last bid
A3: 1 | B3: Duke | C3: ACC | D3: 31–3 | E3: 2 | F3: Automatic | G3: 2024 | I3: 1 | J3: Florida | K3: SEC | L3: 30–4 | M3: 4 | N3: Automatic | O3: 2024 | Q3: 1 | R3: Auburn | S3: SEC | T3: 28–5 | U3: 1 | V3: At Large | W3: 2024 | Y3: 1 | Z3: Houston | AA3: Big 12 | AB3: 30–4 | AC3: 3 | AD3: Automatic | AE3: 2024
A4: 2 | B4: Alabama | C4: SEC | D4: 25–8 | E4: 6 | F4: At Large | G4: 2024 | I4: 2 | J4: St. John's (NY) | K4: Big East | L4: 30–4 | M4: 8 | N4: Automatic | O4: 2019 | Q4: 2 | R4: Michigan State | S4: Big Ten | T4: 27–6 | U4: 7 | V4: At Large | W4: 2024 | Y4: 2 | Z4: Tennessee | AA4: SEC | AB4: 27–7 | AC4: 5 | AD4: At Large | AE4: 2024
A5: 3 | B5: Wisconsin | C5: Big Ten | D5: 26–9 | E5: 12 | F5: At Large | G5: 2024 | I5: 3 | J5: Texas Tech | K5: Big 12 | L5: 25–8 | M5: 9 | N5: At Large | O5: 2024 | Q5: 3 | R5: Iowa State | S5: Big 12 | T5: 24–9 | U5: 10 | V5: At Large | W5: 2024 | Y5: 3 | Z5: Kentucky | AA5: SEC | AB5: 22–11 | AC5: 11 | AD5: At Large | AE5: 2024
A6: 4 | B6: Arizona | C6: Big 12 | D6: 22–12 | E6: 16 | F6: At Large | G6: 2024 | I6: 4 | J6: Maryland | K6: Big Ten | L6: 25–8 | M6: 15 | N6: At Large | O6: 2023 | Q6: 4 | R6: Texas A&M | S6: SEC | T6: 22–10 | U6: 13 | V6: At Large | W6: 2024 | Y6: 4 | Z6: Purdue | AA6: Big Ten | AB6: 22–11 | AC6: 14 | AD6: At Large | AE6: 2024
A7: 5 | B7: Oregon | C7: Big Ten | D7: 24–9 | E7: 19 | F7: At Large | G7: 2024 | I7: 5 | J7: Memphis | K7: American | L7: 29–5 | M7: 20 | N7: Automatic | O7: 2023 | Q7: 5 | R7: Michigan | S7: Big Ten | T7: 25–9 | U7: 17 | V7: Automatic | W7: 2022 | Y7: 5 | Z7: Clemson | AA7: ACC | AB7: 27–6 | AC7: 18 | AD7: At Large | AE7: 2024
A8: 6 | B8: Brigham Young | C8: Big 12 | D8: 24–9 | E8: 21 | F8: At Large | G8: 2024 | I8: 6 | J8: Missouri | K8: SEC | L8: 22–11 | M8: 23 | N8: At Large | O8: 2023 | Q8: 6 | R8: Mississippi | S8: SEC | T8: 22–11 | U8: 24 | V8: At Large | W8: 2019 | Y8: 6 | Z8: Illinois | AA8: Big Ten | AB8: 21–12 | AC8: 22 | AD8: At Large | AE8: 2024
A9: 7 | B9: Saint Mary's (CA) | C9: WCC | D9: 28–5 | E9: 27 | F9: At Large | G9: 2024 | I9: 7 | J9: Kansas | K9: Big 12 | L9: 21–12 | M9: 28 | N9: At Large | O9: 2024 | Q9: 7 | R9: Marquette | S9: Big East | T9: 23–10 | U9: 26 | V9: At Large | W9: 2024 | Y9: 7 | Z9: UCLA | AA9: Big Ten | AB9: 22–10 | AC9: 25 | AD9: At Large | AE9: 2023
A10: 8 | B10: Mississippi State | C10: SEC | D10: 21–12 | E10: 32 | F10: At Large | G10: 2024 | I10: 8 | J10: Connecticut | K10: Big East | L10: 23–10 | M10: 31 | N10: At Large | O10: 2024 | Q10: 8 | R10: Louisville | S10: ACC | T10: 27–7 | U10: 29 | V10: At Large | W10: 2019 | Y10: 8 | Z10: Gonzaga | AA10: WCC | AB10: 25–8 | AC10: 30 | AD10: Automatic | AE10: 2024
A11: 9 | B11: Baylor | C11: Big 12 | D11: 19–14 | E11: 35 | F11: At Large | G11: 2024 | I11: 9 | J11: Oklahoma | K11: SEC | L11: 20–13 | M11: 36 | N11: At Large | O11: 2021 | Q11: 9 | R11: Creighton | S11: Big East | T11: 24–10 | U11: 33 | V11: At Large | W11: 2024 | Y11: 9 | Z11: Georgia | AA11: SEC | AB11: 20–12 | AC11: 34 | AD11: At Large | AE11: 2015
A12: 10 | B12: Vanderbilt | C12: SEC | D12: 20–12 | E12: 39 | F12: At Large | G12: 2017 | I12: 10 | J12: Arkansas | K12: SEC | L12: 20–13 | M12: 37 | N12: At Large | O12: 2023 | Q12: 10 | R12: New Mexico | S12: Mountain West | T12: 26–7 | U12: 38 | V12: At Large | W12: 2024 | Y12: 10 | Z12: Utah State | AA12: Mountain West | AB12: 26–7 | AC12: 40 | AD12: At Large | AE12: 2024
A13: 11 | B13: Virginia Commonwealth | C13: Atlantic 10 | D13: 28–6 | E13: 45 | F13: Automatic | G13: 2023 | I13: 11 | J13: Drake | K13: Missouri Valley | L13: 30–3 | M13: 44 | N13: Automatic | O13: 2024 | Q13: 11 | R13: North Carolina | S13: ACC | T13: 22–13 | U13: 46 | V13: At Large | W13: 2024 | Y13: 11 | Z13: Texas | AA13: SEC | AB13: 19–15 | AC13: 41 | AD13: At Large | AE13: 2024
A14: 12 | B14: Liberty | C14: C-USA | D14: 28–6 | E14: 50 | F14: Automatic | G14: 2021 | I14: 12 | J14: Colorado State | K14: Mountain West | L14: 25–9 | M14: 48 | N14: Automatic | O14: 2024 | Q14: 12 | R14: UC San Diego | S14: Big West | T14: 30–4 | U14: 47 | V14: Automatic | W14: Never | Y14: 12 | Z14: McNeese State | AA14: Southland | AB14: 27–6 | AC14: 49 | AD14: Automatic | AE14: 2024
... A18: 16 | B18: Mount St. Mary's | C18: MAAC | D18: 22–12 | E18: 66 | F18: Automatic | G18: 2021 | I18: 16 | J18: Norfolk State | K18: MEAC | L18: 24–10 | M18: 63 | N18: Automatic | O18: 2022 | Q18: 16 | R18: Alabama State | S18: SWAC | T18: 19–15 | U18: 67 | V18: Automatic | W18: 2011 | Y18: 16 | Z18: SIU Edwardsville | AA18: Ohio Valley | AB18: 22–11 | AC18: 64 | AD18: Automatic | AE18: Never

Sheet Teams
A1: Seed | B1: Region | C1: Team | D1: Hyperlink Name | E1: Logo
A2: 1 | B2: South | C2: Abilene Christian | D2: =_xlfn.XLOOKUP(Teams[[#This Row],[Team]],Team_Links[School],Team_Links[PartialLink],,0,1) -> abilene-christian | E2: =_xlfn.IMAGE(_xlfn.CONCAT("https://cdn.ssref.net/req/202510241/tlogo/ncaa/",TEXT(Teams[[#This Row],[Hyperlink Name]],),"-2025.png")) -> #VALUE!
A3: 16 | B3: South | C3: Air Force | D3: =_xlfn.XLOOKUP(Teams[[#This Row],[Team]],Team_Links[School],Team_Links[PartialLink],,0,1) -> air-force | E3: =_xlfn.IMAGE(_xlfn.CONCAT("https://cdn.ssref.net/req/202510241/tlogo/ncaa/",TEXT(Teams[[#This Row],[Hyperlink Name]],),"-2025.png")) -> #VALUE!
A4: 8 | B4: South | C4: Akron | D4: =_xlfn.XLOOKUP(Teams[[#This Row],[Team]],Team_Links[School],Team_Links[PartialLink],,0,1) -> akron | E4: =_xlfn.IMAGE(_xlfn.CONCAT("https://cdn.ssref.net/req/202510241/tlogo/ncaa/",TEXT(Teams[[#This Row],[Hyperlink Name]],),"-2025.png")) -> #VALUE!
A5: 9 | B5: South | C5: Alabama | D5: =_xlfn.XLOOKUP(Teams[[#This Row],[Team]],Team_Links[School],Team_Links[PartialLink],,0,1) -> alabama | E5: =_xlfn.IMAGE(_xlfn.CONCAT("https://cdn.ssref.net/req/202510241/tlogo/ncaa/",TEXT(Teams[[#This Row],[Hyperlink Name]],),"-2025.png")) -> #VALUE!
A6: 5 | B6: South | C6: Alabama A&M | D6: =_xlfn.XLOOKUP(Teams[[#This Row],[Team]],Team_Links[School],Team_Links[PartialLink],,0,1) -> alabama-am | E6: =_xlfn.IMAGE(_xlfn.CONCAT("https://cdn.ssref.net/req/202510241/tlogo/ncaa/",TEXT(Teams[[#This Row],[Hyperlink Name]],),"-2025.png")) -> #VALUE!
A7: 12 | B7: South | C7: Alabama State | D7: =_xlfn.XLOOKUP(Teams[[#This Row],[Team]],Team_Links[School],Team_Links[PartialLink],,0,1) -> alabama-state | E7: =_xlfn.IMAGE(_xlfn.CONCAT("https://cdn.ssref.net/req/202510241/tlogo/ncaa/",TEXT(Teams[[#This Row],[Hyperlink Name]],),"-2025.png")) -> #VALUE!
A8: 4 | B8: South | C8: Albany (NY) | D8: =_xlfn.XLOOKUP(Teams[[#This Row],[Team]],Team_Links[School],Team_Links[PartialLink],,0,1) -> albany-ny | E8: =_xlfn.IMAGE(_xlfn.CONCAT("https://cdn.ssref.net/req/202510241/tlogo/ncaa/",TEXT(Teams[[#This Row],[Hyperlink Name]],),"-2025.png")) -> #VALUE!
A9: 13 | B9: South | C9: Alcorn State | D9: =_xlfn.XLOOKUP(Teams[[#This Row],[Team]],Team_Links[School],Team_Links[PartialLink],,0,1) -> alcorn-state | E9: =_xlfn.IMAGE(_xlfn.CONCAT("https://cdn.ssref.net/req/202510241/tlogo/ncaa/",TEXT(Teams[[#This Row],[Hyperlink Name]],),"-2025.png")) -> #VALUE!
A10: 6 | B10: South | C10: American | D10: =_xlfn.XLOOKUP(Teams[[#This Row],[Team]],Team_Links[School],Team_Links[PartialLink],,0,1) -> american | E10: =_xlfn.IMAGE(_xlfn.CONCAT("https://cdn.ssref.net/req/202510241/tlogo/ncaa/",TEXT(Teams[[#This Row],[Hyperlink Name]],),"-2025.png")) -> #VALUE!
A11: 11 | B11: South | C11: Appalachian State | D11: =_xlfn.XLOOKUP(Teams[[#This Row],[Team]],Team_Links[School],Team_Links[PartialLink],,0,1) -> appalachian-state | E11: =_xlfn.IMAGE(_xlfn.CONCAT("https://cdn.ssref.net/req/202510241/tlogo/ncaa/",TEXT(Teams[[#This Row],[Hyperlink Name]],),"-2025.png")) -> #VALUE!
A12: 3 | B12: South | C12: Arizona | D12: =_xlfn.XLOOKUP(Teams[[#This Row],[Team]],Team_Links[School],Team_Links[PartialLink],,0,1) -> arizona | E12: =_xlfn.IMAGE(_xlfn.CONCAT("https://cdn.ssref.net/req/202510241/tlogo/ncaa/",TEXT(Teams[[#This Row],[Hyperlink Name]],),"-2025.png")) -> #VALUE!
A13: 14 | B13: South | C13: Arizona State | D13: =_xlfn.XLOOKUP(Teams[[#This Row],[Team]],Team_Links[School],Team_Links[PartialLink],,0,1) -> arizona-state | E13: =_xlfn.IMAGE(_xlfn.CONCAT("https://cdn.ssref.net/req/202510241/tlogo/ncaa/",TEXT(Teams[[#This Row],[Hyperlink Name]],),"-2025.png")) -> #VALUE!
... A65: 15 | B65: Midwest | C65: Dartmouth | D65: =_xlfn.XLOOKUP(Teams[[#This Row],[Team]],Team_Links[School],Team_Links[PartialLink],,0,1) -> dartmouth | E65: =_xlfn.IMAGE(_xlfn.CONCAT("https://cdn.ssref.net/req/202510241/tlogo/ncaa/",TEXT(Teams[[#This Row],[Hyperlink Name]],),"-2025.png")) -> #VALUE!

Sheet Games
G1: Tournament Picks for Multiple Players | S1: .
C3: Loser | D3: Seed Bonus | E3: Game # | F3: Seed | G3: Pairing | J3: Seed | K3: Score 1 | M3: Score 2 | O3: Winner | Q3: Evaluation
A5: =G5 -> Binghamton | B5: =I5 -> Boise State | C5: =IF(O5="","",IF(A5=O5,B5,A5)) -> Boise State | D5: =IF(SeedType=1,0,IF(SeedType=2,VLOOKUP(O5,SeedInfo,2,FALSE)*1,MAX(VLOOKUP(O5,SeedInfo,2,FALSE)-VLOOKUP(C5,SeedInfo,2,FALSE),0))) -> #REF! | E5: 1 | F5: {=_xlfn.XLOOKUP(G5,Teams[[#All],[Team]],Teams[[#All],[Seed]],0,0,1)} -> 13 | G5: =Teams!C25 -> Binghamton | H5: vs | I5: =Teams!C26 -> Boise State | J5: {=_xlfn.XLOOKUP(I5,Teams[[#All],[Team]],Teams[[#All],[Seed]],0,0,1)} -> 6 | K5: =_xlfn.XLOOKUP(G5,Teams!$C:$C,Teams!$E:$E,,0,1) -> #VALUE! | L5: =RANDBETWEEN(90,120) -> 118 | M5: =_xlfn.XLOOKUP(I5,Teams!$C:$C,Teams!$E:$E,,0,1) -> #VALUE! | N5: =RANDBETWEEN(90,120) -> 110 | O5: =IF(L5>N5,G5,I5) -> Binghamton | P5: =_xlfn.XLOOKUP(O5,Teams!$C:$C,Teams!$E:$E,,0,1) -> #VALUE! | Q5: Lorem ipsum dolor sit amet, consectetur adipiscing elit, sed do eiusmod tempor incididunt ut labore et dolore magna aliqua. | R5: =IF( O5=G5, IF(F5>J5,TRUE,FALSE), IF(J5>F5,TRUE,FALSE)) -> TRUE
A6: =G6 -> Boston College | B6: =I6 -> Florida | C6: =IF(O6="","",IF(A6=O6,B6,A6)) -> Boston College | D6: =IF(SeedType=1,0,IF(SeedType=2,VLOOKUP(O6,SeedInfo,2,FALSE)*1,MAX(VLOOKUP(O6,SeedInfo,2,FALSE)-VLOOKUP(C6,SeedInfo,2,FALSE),0))) -> #REF! | E6: 2 | F6: {=_xlfn.XLOOKUP(G6,Teams[[#All],[Team]],Teams[[#All],[Seed]],0,0,1)} -> 11 | G6: =Teams!C27 -> Boston College | H6: vs | I6: =Teams!C28 -> Florida | J6: {=_xlfn.XLOOKUP(I6,Teams[[#All],[Team]],Teams[[#All],[Seed]],0,0,1)} -> 3 | K6: =_xlfn.XLOOKUP(G6,Teams!$C:$C,Teams!$E:$E,,0,1) -> #VALUE! | L6: =RANDBETWEEN(90,120) -> 110 | M6: =_xlfn.XLOOKUP(I6,Teams!$C:$C,Teams!$E:$E,,0,1) -> #VALUE! | N6: =RANDBETWEEN(90,120) -> 120 | O6: =IF(L6>N6,G6,I6) -> Florida | P6: =_xlfn.XLOOKUP(O6,Teams!$C:$C,Teams!$E:$E,,0,1) -> #VALUE! | Q6: Lorem ipsum dolor sit amet, consectetur adipiscing elit, sed do eiusmod tempor incididunt ut labore et dolore magna aliqua. | R6: =IF( O6=G6, IF(F6>J6,TRUE,FALSE), IF(J6>F6,TRUE,FALSE)) -> FALSE
A7: =G7 -> Duke | B7: =I7 -> Bradley | C7: =IF(O7="","",IF(A7=O7,B7,A7)) -> Duke | D7: =IF(SeedType=1,0,IF(SeedType=2,VLOOKUP(O7,SeedInfo,2,FALSE)*1,MAX(VLOOKUP(O7,SeedInfo,2,FALSE)-VLOOKUP(C7,SeedInfo,2,FALSE),0))) -> #REF! | E7: 3 | F7: {=_xlfn.XLOOKUP(G7,Teams[[#All],[Team]],Teams[[#All],[Seed]],0,0,1)} -> 14 | G7: =Teams!C29 -> Duke | H7: vs | I7: =Teams!C30 -> Bradley | J7: {=_xlfn.XLOOKUP(I7,Teams[[#All],[Team]],Teams[[#All],[Seed]],0,0,1)} -> 7 | K7: =_xlfn.XLOOKUP(G7,Teams!$C:$C,Teams!$E:$E,,0,1) -> #VALUE! | L7: =RANDBETWEEN(90,120) -> 94 | M7: =_xlfn.XLOOKUP(I7,Teams!$C:$C,Teams!$E:$E,,0,1) -> #VALUE! | N7: =RANDBETWEEN(90,120) -> 112 | O7: =IF(L7>N7,G7,I7) -> Bradley | P7: =_xlfn.XLOOKUP(O7,Teams!$C:$C,Teams!$E:$E,,0,1) -> #VALUE! | Q7: Lorem ipsum dolor sit amet, consectetur adipiscing elit, sed do eiusmod tempor incididunt ut labore et dolore magna aliqua. | R7: =IF( O7=G7, IF(F7>J7,TRUE,FALSE), IF(J7>F7,TRUE,FALSE)) -> FALSE
A8: =G8 -> Brigham Young | B8: =I8 -> Brown | C8: =IF(O8="","",IF(A8=O8,B8,A8)) -> Brown | D8: =IF(SeedType=1,0,IF(SeedType=2,VLOOKUP(O8,SeedInfo,2,FALSE)*1,MAX(VLOOKUP(O8,SeedInfo,2,FALSE)-VLOOKUP(C8,SeedInfo,2,FALSE),0))) -> #REF! | E8: 4 | F8: {=_xlfn.XLOOKUP(G8,Teams[[#All],[Team]],Teams[[#All],[Seed]],0,0,1)} -> 10 | G8: =Teams!C31 -> Brigham Young | H8: vs | I8: =Teams!C32 -> Brown | J8: {=_xlfn.XLOOKUP(I8,Teams[[#All],[Team]],Teams[[#All],[Seed]],0,0,1)} -> 2 | K8: =_xlfn.XLOOKUP(G8,Teams!$C:$C,Teams!$E:$E,,0,1) -> #VALUE! | L8: =RANDBETWEEN(90,120) -> 117 | M8: =_xlfn.XLOOKUP(I8,Teams!$C:$C,Teams!$E:$E,,0,1) -> #VALUE! | N8: =RANDBETWEEN(90,120) -> 111 | O8: =IF(L8>N8,G8,I8) -> Brigham Young | P8: =_xlfn.XLOOKUP(O8,Teams!$C:$C,Teams!$E:$E,,0,1) -> #VALUE! | Q8: Lorem ipsum dolor sit amet, consectetur adipiscing elit, sed do eiusmod tempor incididunt ut labore et dolore magna aliqua. | R8: =IF( O8=G8, IF(F8>J8,TRUE,FALSE), IF(J8>F8,TRUE,FALSE)) -> TRUE
E9: Game # | F9: First Round | O9: Winner
A10: =G10 -> Abilene Christian | B10: =I10 -> Air Force | C10: =IF(O10="","",IF(A10=O10,B10,A10)) -> Air Force | D10: =IF(SeedType=1,0,IF(SeedType=2,VLOOKUP(O10,SeedInfo,2,FALSE)*1,MAX(VLOOKUP(O10,SeedInfo,2,FALSE)-VLOOKUP(C10,SeedInfo,2,FALSE),0))) -> #REF! | E10: 1 | F10: {=_xlfn.XLOOKUP(G10,Teams[[#All],[Team]],Teams[[#All],[Seed]],0,0,1)} -> 1 | G10: =Teams!C2 -> Abilene Christian | H10: vs | I10: =Teams!C3 -> Air Force | J10: {=_xlfn.XLOOKUP(I10,Teams[[#All],[Team]],Teams[[#All],[Seed]],0,0,1)} -> 16 | K10: =_xlfn.XLOOKUP(G10,Teams!$C:$C,Teams!$E:$E,,0,1) -> #VALUE! | L10: =RANDBETWEEN(90,120) -> 115 | M10: =_xlfn.XLOOKUP(I10,Teams!$C:$C,Teams!$E:$E,,0,1) -> #VALUE! | N10: =RANDBETWEEN(90,120) -> 111 | O10: =IF(L10>N10,G10,I10) -> Abilene Christian | P10: =_xlfn.XLOOKUP(O10,Teams!$C:$C,Teams!$E:$E,,0,1) -> #VALUE! | Q10: Lorem ipsum dolor sit amet, consectetur adipiscing elit, sed do eiusmod tempor incididunt ut labore et dolore magna aliqua. | R10: =IF( O10=G10, IF(F10>J10,TRUE,FALSE), IF(J10>F10,TRUE,FALSE)) -> FALSE
A11: =G11 -> Akron | B11: =I11 -> Alabama | C11: =IF(O11="","",IF(A11=O11,B11,A11)) -> Akron | D11: =IF(SeedType=1,0,IF(SeedType=2,VLOOKUP(O11,SeedInfo,2,FALSE)*1,MAX(VLOOKUP(O11,SeedInfo,2,FALSE)-VLOOKUP(C11,SeedInfo,2,FALSE),0))) -> #REF! | E11: 2 | F11: {=_xlfn.XLOOKUP(G11,Teams[[#All],[Team]],Teams[[#All],[Seed]],0,0,1)} -> 8 | G11: =Teams!C4 -> Akron | H11: vs | I11: =Teams!C5 -> Alabama | J11: {=_xlfn.XLOOKUP(I11,Teams[[#All],[Team]],Teams[[#All],[Seed]],0,0,1)} -> 9 | K11: =_xlfn.XLOOKUP(G11,Teams!$C:$C,Teams!$E:$E,,0,1) -> #VALUE! | L11: =RANDBETWEEN(90,120) -> 97 | M11: =_xlfn.XLOOKUP(I11,Teams!$C:$C,Teams!$E:$E,,0,1) -> #VALUE! | N11: =RANDBETWEEN(90,120) -> 120 | O11: =IF(L11>N11,G11,I11) -> Alabama | P11: =_xlfn.XLOOKUP(O11,Teams!$C:$C,Teams!$E:$E,,0,1) -> #VALUE! | Q11: Lorem ipsum dolor sit amet, consectetur adipiscing elit, sed do eiusmod tempor incididunt ut labore et dolore magna aliqua. | R11: =IF( O11=G11, IF(F11>J11,TRUE,FALSE), IF(J11>F11,TRUE,FALSE)) -> TRUE
A12: =G12 -> Alabama A&M | B12: =I12 -> Arizona | C12: =IF(O12="","",IF(A12=O12,B12,A12)) -> Alabama A&M | D12: =IF(SeedType=1,0,IF(SeedType=2,VLOOKUP(O12,SeedInfo,2,FALSE)*1,MAX(VLOOKUP(O12,SeedInfo,2,FALSE)-VLOOKUP(C12,SeedInfo,2,FALSE),0))) -> #REF! | E12: 3 | F12: {=_xlfn.XLOOKUP(G12,Teams[[#All],[Team]],Teams[[#All],[Seed]],0,0,1)} -> 5 | G12: =Teams!C6 -> Alabama A&M | H12: vs | I12: =Teams[[#This Row],[Team]] -> Arizona | J12: {=_xlfn.XLOOKUP(I12,Teams[[#All],[Team]],Teams[[#All],[Seed]],0,0,1)} -> 3 | K12: =_xlfn.XLOOKUP(G12,Teams!$C:$C,Teams!$E:$E,,0,1) -> #VALUE! | L12: =RANDBETWEEN(90,120) -> 95 | M12: =_xlfn.XLOOKUP(I12,Teams!$C:$C,Teams!$E:$E,,0,1) -> #VALUE! | N12: =RANDBETWEEN(90,120) -> 120 | O12: =IF(L12>N12,G12,I12) -> Arizona | P12: =_xlfn.XLOOKUP(O12,Teams!$C:$C,Teams!$E:$E,,0,1) -> #VALUE! | Q12: Lorem ipsum dolor sit amet, consectetur adipiscing elit, sed do eiusmod tempor incididunt ut labore et dolore magna aliqua. | R12: =IF( O12=G12, IF(F12>J12,TRUE,FALSE), IF(J12>F12,TRUE,FALSE)) -> FALSE
A13: =G13 -> Arizona State | B13: =I13 -> Alcorn State | C13: =IF(O13="","",IF(A13=O13,B13,A13)) -> Arizona State | D13: =IF(SeedType=1,0,IF(SeedType=2,VLOOKUP(O13,SeedInfo,2,FALSE)*1,MAX(VLOOKUP(O13,SeedInfo,2,FALSE)-VLOOKUP(C13,SeedInfo,2,FALSE),0))) -> #REF! | E13: 4 | F13: {=_xlfn.XLOOKUP(G13,Teams[[#All],[Team]],Teams[[#All],[Seed]],0,0,1)} -> 14 | G13: =Teams[[#This Row],[Team]] -> Arizona State | H13: vs | I13: =Teams!C9 -> Alcorn State | J13: {=_xlfn.XLOOKUP(I13,Teams[[#All],[Team]],Teams[[#All],[Seed]],0,0,1)} -> 13 | K13: =_xlfn.XLOOKUP(G13,Teams!$C:$C,Teams!$E:$E,,0,1) -> #VALUE! | L13: =RANDBETWEEN(90,120) -> 103 | M13: =_xlfn.XLOOKUP(I13,Teams!$C:$C,Teams!$E:$E,,0,1) -> #VALUE! | N13: =RANDBETWEEN(90,120) -> 112 | O13: =IF(L13>N13,G13,I13) -> Alcorn State | P13: =_xlfn.XLOOKUP(O13,Teams!$C:$C,Teams!$E:$E,,0,1) -> #VALUE! | Q13: Lorem ipsum dolor sit amet, consectetur adipiscing elit, sed do eiusmod tempor incididunt ut labore et dolore magna aliqua. | R13: =IF( O13=G13, IF(F13>J13,TRUE,FALSE), IF(J13>F13,TRUE,FALSE)) -> FALSE
A14: =G14 -> American | B14: =I14 -> Appalachian State | C14: =IF(O14="","",IF(A14=O14,B14,A14)) -> American | D14: =IF(SeedType=1,0,IF(SeedType=2,VLOOKUP(O14,SeedInfo,2,FALSE)*1,MAX(VLOOKUP(O14,SeedInfo,2,FALSE)-VLOOKUP(C14,SeedInfo,2,FALSE),0))) -> #REF! | E14: 5 | F14: {=_xlfn.XLOOKUP(G14,Teams[[#All],[Team]],Teams[[#All],[Seed]],0,0,1)} -> 6 | G14: =Teams!C10 -> American | H14: vs | I14: =Teams!C11 -> Appalachian State | J14: {=_xlfn.XLOOKUP(I14,Teams[[#All],[Team]],Teams[[#All],[Seed]],0,0,1)} -> 11 | K14: =_xlfn.XLOOKUP(G14,Teams!$C:$C,Teams!$E:$E,,0,1) -> #VALUE! | L14: =RANDBETWEEN(90,120) -> 106 | M14: =_xlfn.XLOOKUP(I14,Teams!$C:$C,Teams!$E:$E,,0,1) -> #VALUE! | N14: =RANDBETWEEN(90,120) -> 120 | O14: =IF(L14>N14,G14,I14) -> Appalachian State | P14: =_xlfn.XLOOKUP(O14,Teams!$C:$C,Teams!$E:$E,,0,1) -> #VALUE! | Q14: Lorem ipsum dolor sit amet, consectetur adipiscing elit, sed do eiusmod tempor incididunt ut labore et dolore magna aliqua. | R14: =IF( O14=G14, IF(F14>J14,TRUE,FALSE), IF(J14>F14,TRUE,FALSE)) -> TRUE
A15: =G15 -> Arizona | B15: =I15 -> Arizona State | C15: =IF(O15="","",IF(A15=O15,B15,A15)) -> Arizona | D15: =IF(SeedType=1,0,IF(SeedType=2,VLOOKUP(O15,SeedInfo,2,FALSE)*1,MAX(VLOOKUP(O15,SeedInfo,2,FALSE)-VLOOKUP(C15,SeedInfo,2,FALSE),0))) -> #REF! | E15: 6 | F15: {=_xlfn.XLOOKUP(G15,Teams[[#All],[Team]],Teams[[#All],[Seed]],0,0,1)} -> 3 | G15: =Teams!C12 -> Arizona | H15: vs | I15: =Teams!C13 -> Arizona State | J15: {=_xlfn.XLOOKUP(I15,Teams[[#All],[Team]],Teams[[#All],[Seed]],0,0,1)} -> 14 | K15: =_xlfn.XLOOKUP(G15,Teams!$C:$C,Teams!$E:$E,,0,1) -> #VALUE! | L15: =RANDBETWEEN(90,120) -> 95 | M15: =_xlfn.XLOOKUP(I15,Teams!$C:$C,Teams!$E:$E,,0,1) -> #VALUE! | N15: =RANDBETWEEN(90,120) -> 115 | O15: =IF(L15>N15,G15,I15) -> Arizona State | P15: =_xlfn.XLOOKUP(O15,Teams!$C:$C,Teams!$E:$E,,0,1) -> #VALUE! | Q15: Lorem ipsum dolor sit amet, consectetur adipiscing elit, sed do eiusmod tempor incididunt ut labore et dolore magna aliqua. | R15: =IF( O15=G15, IF(F15>J15,TRUE,FALSE), IF(J15>F15,TRUE,FALSE)) -> TRUE
A16: =G16 -> Arkansas | B16: =I16 -> Arkansas State | C16: =IF(O16="","",IF(A16=O16,B16,A16)) -> Arkansas State | D16: =IF(SeedType=1,0,IF(SeedType=2,VLOOKUP(O16,SeedInfo,2,FALSE)*1,MAX(VLOOKUP(O16,SeedInfo,2,FALSE)-VLOOKUP(C16,SeedInfo,2,FALSE),0))) -> #REF! | E16: 7 | F16: {=_xlfn.XLOOKUP(G16,Teams[[#All],[Team]],Teams[[#All],[Seed]],0,0,1)} -> 7 | G16: =Teams!C14 -> Arkansas | H16: vs | I16: =Teams!C15 -> Arkansas State | J16: {=_xlfn.XLOOKUP(I16,Teams[[#All],[Team]],Teams[[#All],[Seed]],0,0,1)} -> 10 | K16: =_xlfn.XLOOKUP(G16,Teams!$C:$C,Teams!$E:$E,,0,1) -> #VALUE! | L16: =RANDBETWEEN(90,120) -> 117 | M16: =_xlfn.XLOOKUP(I16,Teams!$C:$C,Teams!$E:$E,,0,1) -> #VALUE! | N16: =RANDBETWEEN(90,120) -> 105 | O16: =IF(L16>N16,G16,I16) -> Arkansas | P16: =_xlfn.XLOOKUP(O16,Teams!$C:$C,Teams!$E:$E,,0,1) -> #VALUE! | Q16: Lorem ipsum dolor sit amet, consectetur adipiscing elit, sed do eiusmod tempor incididunt ut labore et dolore magna aliqua. | R16: =IF( O16=G16, IF(F16>J16,TRUE,FALSE), IF(J16>F16,TRUE,FALSE)) -> FALSE
A17: =G17 -> Arkansas-Pine Bluff | B17: =I17 -> Army | C17: =IF(O17="","",IF(A17=O17,B17,A17)) -> Arkansas-Pine Bluff | D17: =IF(SeedType=1,0,IF(SeedType=2,VLOOKUP(O17,SeedInfo,2,FALSE)*1,MAX(VLOOKUP(O17,SeedInfo,2,FALSE)-VLOOKUP(C17,SeedInfo,2,FALSE),0))) -> #REF! | E17: 8 | F17: {=_xlfn.XLOOKUP(G17,Teams[[#All],[Team]],Teams[[#All],[Seed]],0,0,1)} -> 2 | G17: =Teams!C16 -> Arkansas-Pine Bluff | H17: vs | I17: =Teams!C17 -> Army | J17: {=_xlfn.XLOOKUP(I17,Teams[[#All],[Team]],Teams[[#All],[Seed]],0,0,1)} -> 15 | K17: =_xlfn.XLOOKUP(G17,Teams!$C:$C,Teams!$E:$E,,0,1) -> #VALUE! | L17: =RANDBETWEEN(90,120) -> 96 | M17: =_xlfn.XLOOKUP(I17,Teams!$C:$C,Teams!$E:$E,,0,1) -> #VALUE! | N17: =RANDBETWEEN(90,120) -> 114 | O17: =IF(L17>N17,G17,I17) -> Army | P17: =_xlfn.XLOOKUP(O17,Teams!$C:$C,Teams!$E:$E,,0,1) -> #VALUE! | Q17: Lorem ipsum dolor sit amet, consectetur adipiscing elit, sed do eiusmod tempor incididunt ut labore et dolore magna aliqua. | R17: =IF( O17=G17, IF(F17>J17,TRUE,FALSE), IF(J17>F17,TRUE,FALSE)) -> TRUE
A18: =G18 -> Auburn | B18: =I18 -> Austin Peay | C18: =IF(O18="","",IF(A18=O18,B18,A18)) -> Austin Peay | D18: =IF(SeedType=1,0,IF(SeedType=2,VLOOKUP(O18,SeedInfo,2,FALSE)*1,MAX(VLOOKUP(O18,SeedInfo,2,FALSE)-VLOOKUP(C18,SeedInfo,2,FALSE),0))) -> #REF! | E18: 9 | F18: {=_xlfn.XLOOKUP(G18,Teams[[#All],[Team]],Teams[[#All],[Seed]],0,0,1)} -> 1 | G18: =Teams!C18 -> Auburn | H18: vs | I18: =Teams!C19 -> Austin Peay | J18: {=_xlfn.XLOOKUP(I18,Teams[[#All],[Team]],Teams[[#All],[Seed]],0,0,1)} -> 16 | K18: =_xlfn.XLOOKUP(G18,Teams!$C:$C,Teams!$E:$E,,0,1) -> #VALUE! | L18: =RANDBETWEEN(90,120) -> 113 | M18: =_xlfn.XLOOKUP(I18,Teams!$C:$C,Teams!$E:$E,,0,1) -> #VALUE! | N18: =RANDBETWEEN(90,120) -> 91 | O18: =IF(L18>N18,G18,I18) -> Auburn | P18: =_xlfn.XLOOKUP(O18,Teams!$C:$C,Teams!$E:$E,,0,1) -> #VALUE! | Q18: Lorem ipsum dolor sit amet, consectetur adipiscing elit, sed do eiusmod tempor incididunt ut labore et dolore magna aliqua. | R18: =IF( O18=G18, IF(F18>J18,TRUE,FALSE), IF(J18>F18,TRUE,FALSE)) -> FALSE
A19: =G19 -> Ball State | B19: =I19 -> Baylor | C19: =IF(O19="","",IF(A19=O19,B19,A19)) -> Ball State | D19: =IF(SeedType=1,0,IF(SeedType=2,VLOOKUP(O19,SeedInfo,2,FALSE)*1,MAX(VLOOKUP(O19,SeedInfo,2,FALSE)-VLOOKUP(C19,SeedInfo,2,FALSE),0))) -> #REF! | E19: 10 | F19: {=_xlfn.XLOOKUP(G19,Teams[[#All],[Team]],Teams[[#All],[Seed]],0,0,1)} -> 8 | G19: =Teams!C20 -> Ball State | H19: vs | I19: =Teams!C21 -> Baylor | J19: {=_xlfn.XLOOKUP(I19,Teams[[#All],[Team]],Teams[[#All],[Seed]],0,0,1)} -> 9 | K19: =_xlfn.XLOOKUP(G19,Teams!$C:$C,Teams!$E:$E,,0,1) -> #VALUE! | L19: =RANDBETWEEN(90,120) -> 90 | M19: =_xlfn.XLOOKUP(I19,Teams!$C:$C,Teams!$E:$E,,0,1) -> #VALUE! | N19: =RANDBETWEEN(90,120) -> 90 | O19: =IF(L19>N19,G19,I19) -> Baylor | P19: =_xlfn.XLOOKUP(O19,Teams!$C:$C,Teams!$E:$E,,0,1) -> #VALUE! | Q19: Lorem ipsum dolor sit amet, consectetur adipiscing elit, sed do eiusmod tempor incididunt ut labore et dolore magna aliqua. | R19: =IF( O19=G19, IF(F19>J19,TRUE,FALSE), IF(J19>F19,TRUE,FALSE)) -> TRUE
A20: =G20 -> Bellarmine | B20: =I20 -> Belmont | C20: =IF(O20="","",IF(A20=O20,B20,A20)) -> Bellarmine | D20: =IF(SeedType=1,0,IF(SeedType=2,VLOOKUP(O20,SeedInfo,2,FALSE)*1,MAX(VLOOKUP(O20,SeedInfo,2,FALSE)-VLOOKUP(C20,SeedInfo,2,FALSE),0))) -> #REF! | E20: 11 | F20: {=_xlfn.XLOOKUP(G20,Teams[[#All],[Team]],Teams[[#All],[Seed]],0,0,1)} -> 5 | G20: =Teams!C22 -> Bellarmine | H20: vs | I20: =Teams!C23 -> Belmont | J20: {=_xlfn.XLOOKUP(I20,Teams[[#All],[Team]],Teams[[#All],[Seed]],0,0,1)} -> 12 | K20: =_xlfn.XLOOKUP(G20,Teams!$C:$C,Teams!$E:$E,,0,1) -> #VALUE! | L20: =RANDBETWEEN(90,120) -> 113 | M20: =_xlfn.XLOOKUP(I20,Teams!$C:$C,Teams!$E:$E,,0,1) -> #VALUE! | N20: =RANDBETWEEN(90,120) -> 119 | O20: =IF(L20>N20,G20,I20) -> Belmont | P20: =_xlfn.XLOOKUP(O20,Teams!$C:$C,Teams!$E:$E,,0,1) -> #VALUE! | Q20: Lorem ipsum dolor sit amet, consectetur adipiscing elit, sed do eiusmod tempor incididunt ut labore et dolore magna aliqua. | R20: =IF( O20=G20, IF(F20>J20,TRUE,FALSE), IF(J20>F20,TRUE,FALSE)) -> TRUE
A21: =G21 -> Bethune-Cookman | B21: =I21 -> Binghamton | C21: =IF(O21="","",IF(A21=O21,B21,A21)) -> Binghamton | D21: =IF(SeedType=1,0,IF(SeedType=2,VLOOKUP(O21,SeedInfo,2,FALSE)*1,MAX(VLOOKUP(O21,SeedInfo,2,FALSE)-VLOOKUP(C21,SeedInfo,2,FALSE),0))) -> #REF! | E21: 12 | F21: {=_xlfn.XLOOKUP(G21,Teams[[#All],[Team]],Teams[[#All],[Seed]],0,0,1)} -> 4 | G21: =Teams!C24 -> Bethune-Cookman | H21: vs | I21: =Teams!C25 -> Binghamton | J21: {=_xlfn.XLOOKUP(I21,Teams[[#All],[Team]],Teams[[#All],[Seed]],0,0,1)} -> 13 | K21: =_xlfn.XLOOKUP(G21,Teams!$C:$C,Teams!$E:$E,,0,1) -> #VALUE! | L21: =RANDBETWEEN(90,120) -> 106 | M21: =_xlfn.XLOOKUP(I21,Teams!$C:$C,Teams!$E:$E,,0,1) -> #VALUE! | N21: =RANDBETWEEN(90,120) -> 90 | O21: =IF(L21>N21,G21,I21) -> Bethune-Cookman | P21: =_xlfn.XLOOKUP(O21,Teams!$C:$C,Teams!$E:$E,,0,1) -> #VALUE! | Q21: Lorem ipsum dolor sit amet, consectetur adipiscing elit, sed do eiusmod tempor incididunt ut labore et dolore magna aliqua. | R21: =IF( O21=G21, IF(F21>J21,TRUE,FALSE), IF(J21>F21,TRUE,FALSE)) -> FALSE
A22: =G22 -> Boise State | B22: =I22 -> Boston College | C22: =IF(O22="","",IF(A22=O22,B22,A22)) -> Boston College | D22: =IF(SeedType=1,0,IF(SeedType=2,VLOOKUP(O22,SeedInfo,2,FALSE)*1,MAX(VLOOKUP(O22,SeedInfo,2,FALSE)-VLOOKUP(C22,SeedInfo,2,FALSE),0))) -> #REF! | E22: 13 | F22: {=_xlfn.XLOOKUP(G22,Teams[[#All],[Team]],Teams[[#All],[Seed]],0,0,1)} -> 6 | G22: =Teams!C26 -> Boise State | H22: vs | I22: =Teams!C27 -> Boston College | J22: {=_xlfn.XLOOKUP(I22,Teams[[#All],[Team]],Teams[[#All],[Seed]],0,0,1)} -> 11 | K22: =_xlfn.XLOOKUP(G22,Teams!$C:$C,Teams!$E:$E,,0,1) -> #VALUE! | L22: =RANDBETWEEN(90,120) -> 106 | M22: =_xlfn.XLOOKUP(I22,Teams!$C:$C,Teams!$E:$E,,0,1) -> #VALUE! | N22: =RANDBETWEEN(90,120) -> 104 | O22: =IF(L22>N22,G22,I22) -> Boise State | P22: =_xlfn.XLOOKUP(O22,Teams!$C:$C,Teams!$E:$E,,0,1) -> #VALUE! | Q22: Lorem ipsum dolor sit amet, consectetur adipiscing elit, sed do eiusmod tempor incididunt ut labore et dolore magna aliqua. | R22: =IF( O22=G22, IF(F22>J22,TRUE,FALSE), IF(J22>F22,TRUE,FALSE)) -> FALSE
A23: =G23 -> Florida | B23: =I23 -> Duke | C23: =IF(O23="","",IF(A23=O23,B23,A23)) -> Florida | D23: =IF(SeedType=1,0,IF(SeedType=2,VLOOKUP(O23,SeedInfo,2,FALSE)*1,MAX(VLOOKUP(O23,SeedInfo,2,FALSE)-VLOOKUP(C23,SeedInfo,2,FALSE),0))) -> #REF! | E23: 14 | F23: {=_xlfn.XLOOKUP(G23,Teams[[#All],[Team]],Teams[[#All],[Seed]],0,0,1)} -> 3 | G23: =Teams!C28 -> Florida | H23: vs | I23: =Teams!C29 -> Duke | J23: {=_xlfn.XLOOKUP(I23,Teams[[#All],[Team]],Teams[[#All],[Seed]],0,0,1)} -> 14 | K23: =_xlfn.XLOOKUP(G23,Teams!$C:$C,Teams!$E:$E,,0,1) -> #VALUE! | L23: =RANDBETWEEN(90,120) -> 110 | M23: =_xlfn.XLOOKUP(I23,Teams!$C:$C,Teams!$E:$E,,0,1) -> #VALUE! | N23: =RANDBETWEEN(90,120) -> 117 | O23: =IF(L23>N23,G23,I23) -> Duke | P23: =_xlfn.XLOOKUP(O23,Teams!$C:$C,Teams!$E:$E,,0,1) -> #VALUE! | Q23: Lorem ipsum dolor sit amet, consectetur adipiscing elit, sed do eiusmod tempor incididunt ut labore et dolore magna aliqua. | R23: =IF( O23=G23, IF(F23>J23,TRUE,FALSE), IF(J23>F23,TRUE,FALSE)) -> TRUE
A24: =G24 -> Bradley | B24: =I24 -> Brigham Young | C24: =IF(O24="","",IF(A24=O24,B24,A24)) -> Bradley | D24: =IF(SeedType=1,0,IF(SeedType=2,VLOOKUP(O24,SeedInfo,2,FALSE)*1,MAX(VLOOKUP(O24,SeedInfo,2,FALSE)-VLOOKUP(C24,SeedInfo,2,FALSE),0))) -> #REF! | E24: 15 | F24: {=_xlfn.XLOOKUP(G24,Teams[[#All],[Team]],Teams[[#All],[Seed]],0,0,1)} -> 7 | G24: =Teams!C30 -> Bradley | H24: vs | I24: =Teams!C31 -> Brigham Young | J24: {=_xlfn.XLOOKUP(I24,Teams[[#All],[Team]],Teams[[#All],[Seed]],0,0,1)} -> 10 | K24: =_xlfn.XLOOKUP(G24,Teams!$C:$C,Teams!$E:$E,,0,1) -> #VALUE! | L24: =RANDBETWEEN(90,120) -> 99 | M24: =_xlfn.XLOOKUP(I24,Teams!$C:$C,Teams!$E:$E,,0,1) -> #VALUE! | N24: =RANDBETWEEN(90,120) -> 110 | O24: =IF(L24>N24,G24,I24) -> Brigham Young | P24: =_xlfn.XLOOKUP(O24,Teams!$C:$C,Teams!$E:$E,,0,1) -> #VALUE! | Q24: Lorem ipsum dolor sit amet, consectetur adipiscing elit, sed do eiusmod tempor incididunt ut labore et dolore magna aliqua. | R24: =IF( O24=G24, IF(F24>J24,TRUE,FALSE), IF(J24>F24,TRUE,FALSE)) -> TRUE
A25: =G25 -> Brown | B25: =I25 -> Bryant | C25: =IF(O25="","",IF(A25=O25,B25,A25)) -> Brown | D25: =IF(SeedType=1,0,IF(SeedType=2,VLOOKUP(O25,SeedInfo,2,FALSE)*1,MAX(VLOOKUP(O25,SeedInfo,2,FALSE)-VLOOKUP(C25,SeedInfo,2,FALSE),0))) -> #REF! | E25: 16 | F25: {=_xlfn.XLOOKUP(G25,Teams[[#All],[Team]],Teams[[#All],[Seed]],0,0,1)} -> 2 | G25: =Teams!C32 -> Brown | H25: vs | I25: =Teams!C33 -> Bryant | J25: {=_xlfn.XLOOKUP(I25,Teams[[#All],[Team]],Teams[[#All],[Seed]],0,0,1)} -> 15 | K25: =_xlfn.XLOOKUP(G25,Teams!$C:$C,Teams!$E:$E,,0,1) -> #VALUE! | L25: =RANDBETWEEN(90,120) -> 107 | M25: =_xlfn.XLOOKUP(I25,Teams!$C:$C,Teams!$E:$E,,0,1) -> #VALUE! | N25: =RANDBETWEEN(90,120) -> 107 | O25: =IF(L25>N25,G25,I25) -> Bryant | P25: =_xlfn.XLOOKUP(O25,Teams!$C:$C,Teams!$E:$E,,0,1) -> #VALUE! | Q25: Lorem ipsum dolor sit amet, consectetur adipiscing elit, sed do eiusmod tempor incididunt ut labore et dolore magna aliqua. | R25: =IF( O25=G25, IF(F25>J25,TRUE,FALSE), IF(J25>F25,TRUE,FALSE)) -> TRUE
A26: =G26 -> Bucknell | B26: =I26 -> Buffalo | C26: =IF(O26="","",IF(A26=O26,B26,A26)) -> Buffalo | D26: =IF(SeedType=1,0,IF(SeedType=2,VLOOKUP(O26,SeedInfo,2,FALSE)*1,MAX(VLOOKUP(O26,SeedInfo,2,FALSE)-VLOOKUP(C26,SeedInfo,2,FALSE),0))) -> #REF! | E26: 17 | F26: {=_xlfn.XLOOKUP(G26,Teams[[#All],[Team]],Teams[[#All],[Seed]],0,0,1)} -> 1 | G26: =Teams!C34 -> Bucknell | H26: vs | I26: =Teams!C35 -> Buffalo | J26: {=_xlfn.XLOOKUP(I26,Teams[[#All],[Team]],Teams[[#All],[Seed]],0,0,1)} -> 16 | K26: =_xlfn.XLOOKUP(G26,Teams!$C:$C,Teams!$E:$E,,0,1) -> #VALUE! | L26: =RANDBETWEEN(90,120) -> 118 | M26: =_xlfn.XLOOKUP(I26,Teams!$C:$C,Teams!$E:$E,,0,1) -> #VALUE! | N26: =RANDBETWEEN(90,120) -> 98 | O26: =IF(L26>N26,G26,I26) -> Bucknell | P26: =_xlfn.XLOOKUP(O26,Teams!$C:$C,Teams!$E:$E,,0,1) -> #VALUE! | Q26: Lorem ipsum dolor sit amet, consectetur adipiscing elit, sed do eiusmod tempor incididunt ut labore et dolore magna aliqua. | R26: =IF( O26=G26, IF(F26>J26,TRUE,FALSE), IF(J26>F26,TRUE,FALSE)) -> FALSE
A27: =G27 -> Butler | B27: =I27 -> Cal Poly | C27: =IF(O27="","",IF(A27=O27,B27,A27)) -> Cal Poly | D27: =IF(SeedType=1,0,IF(SeedType=2,VLOOKUP(O27,SeedInfo,2,FALSE)*1,MAX(VLOOKUP(O27,SeedInfo,2,FALSE)-VLOOKUP(C27,SeedInfo,2,FALSE),0))) -> #REF! | E27: 18 | F27: {=_xlfn.XLOOKUP(G27,Teams[[#All],[Team]],Teams[[#All],[Seed]],0,0,1)} -> 8 | G27: =Teams!C36 -> Butler | H27: vs | I27: =Teams!C37 -> Cal Poly | J27: {=_xlfn.XLOOKUP(I27,Teams[[#All],[Team]],Teams[[#All],[Seed]],0,0,1)} -> 9 | K27: =_xlfn.XLOOKUP(G27,Teams!$C:$C,Teams!$E:$E,,0,1) -> #VALUE! | L27: =RANDBETWEEN(90,120) -> 109 | M27: =_xlfn.XLOOKUP(I27,Teams!$C:$C,Teams!$E:$E,,0,1) -> #VALUE! | N27: =RANDBETWEEN(90,120) -> 92 | O27: =IF(L27>N27,G27,I27) -> Butler | P27: =_xlfn.XLOOKUP(O27,Teams!$C:$C,Teams!$E:$E,,0,1) -> #VALUE! | Q27: Lorem ipsum dolor sit amet, consectetur adipiscing elit, sed do eiusmod tempor incididunt ut labore et dolore magna aliqua. | R27: =IF( O27=G27, IF(F27>J27,TRUE,FALSE), IF(J27>F27,TRUE,FALSE)) -> FALSE
A28: =G28 -> Cal State Bakersfield | B28: =I28 -> Cal State Fullerton | C28: =IF(O28="","",IF(A28=O28,B28,A28)) -> Cal State Bakersfield | D28: =IF(SeedType=1,0,IF(SeedType=2,VLOOKUP(O28,SeedInfo,2,FALSE)*1,MAX(VLOOKUP(O28,SeedInfo,2,FALSE)-VLOOKUP(C28,SeedInfo,2,FALSE),0))) -> #REF! | E28: 19 | F28: {=_xlfn.XLOOKUP(G28,Teams[[#All],[Team]],Teams[[#All],[Seed]],0,0,1)} -> 5 | G28: =Teams!C38 -> Cal State Bakersfield | H28: vs | I28: =Teams!C39 -> Cal State Fullerton | J28: {=_xlfn.XLOOKUP(I28,Teams[[#All],[Team]],Teams[[#All],[Seed]],0,0,1)} -> 12 | K28: =_xlfn.XLOOKUP(G28,Teams!$C:$C,Teams!$E:$E,,0,1) -> #VALUE! | L28: =RANDBETWEEN(90,120) -> 91 | M28: =_xlfn.XLOOKUP(I28,Teams!$C:$C,Teams!$E:$E,,0,1) -> #VALUE! | N28: =RANDBETWEEN(90,120) -> 100 | O28: =IF(L28>N28,G28,I28) -> Cal State Fullerton | P28: =_xlfn.XLOOKUP(O28,Teams!$C:$C,Teams!$E:$E,,0,1) -> #VALUE! | Q28: Lorem ipsum dolor sit amet, consectetur adipiscing elit, sed do eiusmod tempor incididunt ut labore et dolore magna aliqua. | R28: =IF( O28=G28, IF(F28>J28,TRUE,FALSE), IF(J28>F28,TRUE,FALSE)) -> TRUE
A29: =G29 -> Cal State Northridge | B29: =I29 -> California | C29: =IF(O29="","",IF(A29=O29,B29,A29)) -> California | D29: =IF(SeedType=1,0,IF(SeedType=2,VLOOKUP(O29,SeedInfo,2,FALSE)*1,MAX(VLOOKUP(O29,SeedInfo,2,FALSE)-VLOOKUP(C29,SeedInfo,2,FALSE),0))) -> #REF! | E29: 20 | F29: {=_xlfn.XLOOKUP(G29,Teams[[#All],[Team]],Teams[[#All],[Seed]],0,0,1)} -> 4 | G29: =Teams!C40 -> Cal State Northridge | H29: vs | I29: =Teams!C41 -> California | J29: {=_xlfn.XLOOKUP(I29,Teams[[#All],[Team]],Teams[[#All],[Seed]],0,0,1)} -> 13 | K29: =_xlfn.XLOOKUP(G29,Teams!$C:$C,Teams!$E:$E,,0,1) -> #VALUE! | L29: =RANDBETWEEN(90,120) -> 116 | M29: =_xlfn.XLOOKUP(I29,Teams!$C:$C,Teams!$E:$E,,0,1) -> #VALUE! | N29: =RANDBETWEEN(90,120) -> 115 | O29: =IF(L29>N29,G29,I29) -> Cal State Northridge | P29: =_xlfn.XLOOKUP(O29,Teams!$C:$C,Teams!$E:$E,,0,1) -> #VALUE! | Q29: Lorem ipsum dolor sit amet, consectetur adipiscing elit, sed do eiusmod tempor incididunt ut labore et dolore magna aliqua. | R29: =IF( O29=G29, IF(F29>J29,TRUE,FALSE), IF(J29>F29,TRUE,FALSE)) -> FALSE
A30: =G30 -> California Baptist | B30: =I30 -> Campbell | C30: =IF(O30="","",IF(A30=O30,B30,A30)) -> Campbell | D30: =IF(SeedType=1,0,IF(SeedType=2,VLOOKUP(O30,SeedInfo,2,FALSE)*1,MAX(VLOOKUP(O30,SeedInfo,2,FALSE)-VLOOKUP(C30,SeedInfo,2,FALSE),0))) -> #REF! | E30: 21 | F30: {=_xlfn.XLOOKUP(G30,Teams[[#All],[Team]],Teams[[#All],[Seed]],0,0,1)} -> 6 | G30: =Teams!C42 -> California Baptist | H30: vs | I30: =Teams!C43 -> Campbell | J30: {=_xlfn.XLOOKUP(I30,Teams[[#All],[Team]],Teams[[#All],[Seed]],0,0,1)} -> 11 | K30: =_xlfn.XLOOKUP(G30,Teams!$C:$C,Teams!$E:$E,,0,1) -> #VALUE! | L30: =RANDBETWEEN(90,120) -> 108 | M30: =_xlfn.XLOOKUP(I30,Teams!$C:$C,Teams!$E:$E,,0,1) -> #VALUE! | N30: =RANDBETWEEN(90,120) -> 94 | O30: =IF(L30>N30,G30,I30) -> California Baptist | P30: =_xlfn.XLOOKUP(O30,Teams!$C:$C,Teams!$E:$E,,0,1) -> #VALUE! | Q30: Lorem ipsum dolor sit amet, consectetur adipiscing elit, sed do eiusmod tempor incididunt ut labore et dolore magna aliqua. | R30: =IF( O30=G30, IF(F30>J30,TRUE,FALSE), IF(J30>F30,TRUE,FALSE)) -> FALSE
A31: =G31 -> Canisius | B31: =I31 -> Central Arkansas | C31: =IF(O31="","",IF(A31=O31,B31,A31)) -> Canisius | D31: =IF(SeedType=1,0,IF(SeedType=2,VLOOKUP(O31,SeedInfo,2,FALSE)*1,MAX(VLOOKUP(O31,SeedInfo,2,FALSE)-VLOOKUP(C31,SeedInfo,2,FALSE),0))) -> #REF! | E31: 22 | F31: {=_xlfn.XLOOKUP(G31,Teams[[#All],[Team]],Teams[[#All],[Seed]],0,0,1)} -> 3 | G31: =Teams!C44 -> Canisius | H31: vs | I31: =Teams!C45 -> Central Arkansas | J31: {=_xlfn.XLOOKUP(I31,Teams[[#All],[Team]],Teams[[#All],[Seed]],0,0,1)} -> 14 | K31: =_xlfn.XLOOKUP(G31,Teams!$C:$C,Teams!$E:$E,,0,1) -> #VALUE! | L31: =RANDBETWEEN(90,120) -> 104 | M31: =_xlfn.XLOOKUP(I31,Teams!$C:$C,Teams!$E:$E,,0,1) -> #VALUE! | N31: =RANDBETWEEN(90,120) -> 116 | O31: =IF(L31>N31,G31,I31) -> Central Arkansas | P31: =_xlfn.XLOOKUP(O31,Teams!$C:$C,Teams!$E:$E,,0,1) -> #VALUE! | Q31: Lorem ipsum dolor sit amet, consectetur adipiscing elit, sed do eiusmod tempor incididunt ut labore et dolore magna aliqua. | R31: =IF( O31=G31, IF(F31>J31,TRUE,FALSE), IF(J31>F31,TRUE,FALSE)) -> TRUE
A32: =G32 -> Central Connecticut State | B32: =I32 -> Central Michigan | C32: =IF(O32="","",IF(A32=O32,B32,A32)) -> Central Connecticut State | D32: =IF(SeedType=1,0,IF(SeedType=2,VLOOKUP(O32,SeedInfo,2,FALSE)*1,MAX(VLOOKUP(O32,SeedInfo,2,FALSE)-VLOOKUP(C32,SeedInfo,2,FALSE),0))) -> #REF! | E32: 23 | F32: {=_xlfn.XLOOKUP(G32,Teams[[#All],[Team]],Teams[[#All],[Seed]],0,0,1)} -> 7 | G32: =Teams!C46 -> Central Connecticut State | H32: vs | I32: =Teams!C47 -> Central Michigan | J32: {=_xlfn.XLOOKUP(I32,Teams[[#All],[Team]],Teams[[#All],[Seed]],0,0,1)} -> 10 | K32: =_xlfn.XLOOKUP(G32,Teams!$C:$C,Teams!$E:$E,,0,1) -> #VALUE! | L32: =RANDBETWEEN(90,120) -> 91 | M32: =_xlfn.XLOOKUP(I32,Teams!$C:$C,Teams!$E:$E,,0,1) -> #VALUE! | N32: =RANDBETWEEN(90,120) -> 99 | O32: =IF(L32>N32,G32,I32) -> Central Michigan | P32: =_xlfn.XLOOKUP(O32,Teams!$C:$C,Teams!$E:$E,,0,1) -> #VALUE! | Q32: Lorem ipsum dolor sit amet, consectetur adipiscing elit, sed do eiusmod tempor incididunt ut labore et dolore magna aliqua. | R32: =IF( O32=G32, IF(F32>J32,TRUE,FALSE), IF(J32>F32,TRUE,FALSE)) -> TRUE
A33: =G33 -> Charleston Southern | B33: =I33 -> Charlotte | C33: =IF(O33="","",IF(A33=O33,B33,A33)) -> Charleston Southern | D33: =IF(SeedType=1,0,IF(SeedType=2,VLOOKUP(O33,SeedInfo,2,FALSE)*1,MAX(VLOOKUP(O33,SeedInfo,2,FALSE)-VLOOKUP(C33,SeedInfo,2,FALSE),0))) -> #REF! | E33: 24 | F33: {=_xlfn.XLOOKUP(G33,Teams[[#All],[Team]],Teams[[#All],[Seed]],0,0,1)} -> 2 | G33: =Teams!C48 -> Charleston Southern | H33: vs | I33: =Teams!C49 -> Charlotte | J33: {=_xlfn.XLOOKUP(I33,Teams[[#All],[Team]],Teams[[#All],[Seed]],0,0,1)} -> 15 | K33: =_xlfn.XLOOKUP(G33,Teams!$C:$C,Teams!$E:$E,,0,1) -> #VALUE! | L33: =RANDBETWEEN(90,120) -> 92 | M33: =_xlfn.XLOOKUP(I33,Teams!$C:$C,Teams!$E:$E,,0,1) -> #VALUE! | N33: =RANDBETWEEN(90,120) -> 101 | O33: =IF(L33>N33,G33,I33) -> Charlotte | P33: =_xlfn.XLOOKUP(O33,Teams!$C:$C,Teams!$E:$E,,0,1) -> #VALUE! | Q33: Lorem ipsum dolor sit amet, consectetur adipiscing elit, sed do eiusmod tempor incididunt ut labore et dolore magna aliqua. | R33: =IF( O33=G33, IF(F33>J33,TRUE,FALSE), IF(J33>F33,TRUE,FALSE)) -> TRUE
A34: =G34 -> Chattanooga | B34: =I34 -> Chicago State | C34: =IF(O34="","",IF(A34=O34,B34,A34)) -> Chattanooga | D34: =IF(SeedType=1,0,IF(SeedType=2,VLOOKUP(O34,SeedInfo,2,FALSE)*1,MAX(VLOOKUP(O34,SeedInfo,2,FALSE)-VLOOKUP(C34,SeedInfo,2,FALSE),0))) -> #REF! | E34: 25 | F34: {=_xlfn.XLOOKUP(G34,Teams[[#All],[Team]],Teams[[#All],[Seed]],0,0,1)} -> 1 | G34: =Teams!C50 -> Chattanooga | H34: vs | I34: =Teams!C51 -> Chicago State | J34: {=_xlfn.XLOOKUP(I34,Teams[[#All],[Team]],Teams[[#All],[Seed]],0,0,1)} -> 16 | K34: =_xlfn.XLOOKUP(G34,Teams!$C:$C,Teams!$E:$E,,0,1) -> #VALUE! | L34: =RANDBETWEEN(90,120) -> 93 | M34: =_xlfn.XLOOKUP(I34,Teams!$C:$C,Teams!$E:$E,,0,1) -> #VALUE! | N34: =RANDBETWEEN(90,120) -> 118 | O34: =IF(L34>N34,G34,I34) -> Chicago State | P34: =_xlfn.XLOOKUP(O34,Teams!$C:$C,Teams!$E:$E,,0,1) -> #VALUE! | Q34: Lorem ipsum dolor sit amet, consectetur adipiscing elit, sed do eiusmod tempor incididunt ut labore et dolore magna aliqua. | R34: =IF( O34=G34, IF(F34>J34,TRUE,FALSE), IF(J34>F34,TRUE,FALSE)) -> TRUE
A35: =G35 -> Cincinnati | B35: =I35 -> Clemson | C35: =IF(O35="","",IF(A35=O35,B35,A35)) -> Cincinnati | D35: =IF(SeedType=1,0,IF(SeedType=2,VLOOKUP(O35,SeedInfo,2,FALSE)*1,MAX(VLOOKUP(O35,SeedInfo,2,FALSE)-VLOOKUP(C35,SeedInfo,2,FALSE),0))) -> #REF! | E35: 26 | F35: {=_xlfn.XLOOKUP(G35,Teams[[#All],[Team]],Teams[[#All],[Seed]],0,0,1)} -> 8 | G35: =Teams!C52 -> Cincinnati | H35: vs | I35: =Teams!C53 -> Clemson | J35: {=_xlfn.XLOOKUP(I35,Teams[[#All],[Team]],Teams[[#All],[Seed]],0,0,1)} -> 9 | K35: =_xlfn.XLOOKUP(G35,Teams!$C:$C,Teams!$E:$E,,0,1) -> #VALUE! | L35: =RANDBETWEEN(90,120) -> 100 | M35: =_xlfn.XLOOKUP(I35,Teams!$C:$C,Teams!$E:$E,,0,1) -> #VALUE! | N35: =RANDBETWEEN(90,120) -> 114 | O35: =IF(L35>N35,G35,I35) -> Clemson | P35: =_xlfn.XLOOKUP(O35,Teams!$C:$C,Teams!$E:$E,,0,1) -> #VALUE! | Q35: Lorem ipsum dolor sit amet, consectetur adipiscing elit, sed do eiusmod tempor incididunt ut labore et dolore magna aliqua. | R35: =IF( O35=G35, IF(F35>J35,TRUE,FALSE), IF(J35>F35,TRUE,FALSE)) -> TRUE
A36: =G36 -> Cleveland State | B36: =I36 -> Coastal Carolina | C36: =IF(O36="","",IF(A36=O36,B36,A36)) -> Coastal Carolina | D36: =IF(SeedType=1,0,IF(SeedType=2,VLOOKUP(O36,SeedInfo,2,FALSE)*1,MAX(VLOOKUP(O36,SeedInfo,2,FALSE)-VLOOKUP(C36,SeedInfo,2,FALSE),0))) -> #REF! | E36: 27 | F36: {=_xlfn.XLOOKUP(G36,Teams[[#All],[Team]],Teams[[#All],[Seed]],0,0,1)} -> 5 | G36: =Teams!C54 -> Cleveland State | H36: vs | I36: =Teams!C55 -> Coastal Carolina | J36: {=_xlfn.XLOOKUP(I36,Teams[[#All],[Team]],Teams[[#All],[Seed]],0,0,1)} -> 12 | K36: =_xlfn.XLOOKUP(G36,Teams!$C:$C,Teams!$E:$E,,0,1) -> #VALUE! | L36: =RANDBETWEEN(90,120) -> 119 | M36: =_xlfn.XLOOKUP(I36,Teams!$C:$C,Teams!$E:$E,,0,1) -> #VALUE! | N36: =RANDBETWEEN(90,120) -> 96 | O36: =IF(L36>N36,G36,I36) -> Cleveland State | P36: =_xlfn.XLOOKUP(O36,Teams!$C:$C,Teams!$E:$E,,0,1) -> #VALUE! | Q36: Lorem ipsum dolor sit amet, consectetur adipiscing elit, sed do eiusmod tempor incididunt ut labore et dolore magna aliqua. | R36: =IF( O36=G36, IF(F36>J36,TRUE,FALSE), IF(J36>F36,TRUE,FALSE)) -> FALSE
A37: =G37 -> Colgate | B37: =I37 -> College of Charleston | C37: =IF(O37="","",IF(A37=O37,B37,A37)) -> Colgate | D37: =IF(SeedType=1,0,IF(SeedType=2,VLOOKUP(O37,SeedInfo,2,FALSE)*1,MAX(VLOOKUP(O37,SeedInfo,2,FALSE)-VLOOKUP(C37,SeedInfo,2,FALSE),0))) -> #REF! | E37: 28 | F37: {=_xlfn.XLOOKUP(G37,Teams[[#All],[Team]],Teams[[#All],[Seed]],0,0,1)} -> 4 | G37: =Teams!C56 -> Colgate | H37: vs | I37: =Teams!C57 -> College of Charleston | J37: {=_xlfn.XLOOKUP(I37,Teams[[#All],[Team]],Teams[[#All],[Seed]],0,0,1)} -> 13 | K37: =_xlfn.XLOOKUP(G37,Teams!$C:$C,Teams!$E:$E,,0,1) -> #VALUE! | L37: =RANDBETWEEN(90,120) -> 103 | M37: =_xlfn.XLOOKUP(I37,Teams!$C:$C,Teams!$E:$E,,0,1) -> #VALUE! | N37: =RANDBETWEEN(90,120) -> 108 | O37: =IF(L37>N37,G37,I37) -> College of Charleston | P37: =_xlfn.XLOOKUP(O37,Teams!$C:$C,Teams!$E:$E,,0,1) -> #VALUE! | Q37: Lorem ipsum dolor sit amet, consectetur adipiscing elit, sed do eiusmod tempor incididunt ut labore et dolore magna aliqua. | R37: =IF( O37=G37, IF(F37>J37,TRUE,FALSE), IF(J37>F37,TRUE,FALSE)) -> TRUE
A38: =G38 -> Colorado | B38: =I38 -> Colorado State | C38: =IF(O38="","",IF(A38=O38,B38,A38)) -> Colorado | D38: =IF(SeedType=1,0,IF(SeedType=2,VLOOKUP(O38,SeedInfo,2,FALSE)*1,MAX(VLOOKUP(O38,SeedInfo,2,FALSE)-VLOOKUP(C38,SeedInfo,2,FALSE),0))) -> #REF! | E38: 29 | F38: {=_xlfn.XLOOKUP(G38,Teams[[#All],[Team]],Teams[[#All],[Seed]],0,0,1)} -> 6 | G38: =Teams!C58 -> Colorado | H38: vs | I38: =Teams!C59 -> Colorado State | J38: {=_xlfn.XLOOKUP(I38,Teams[[#All],[Team]],Teams[[#All],[Seed]],0,0,1)} -> 11 | K38: =_xlfn.XLOOKUP(G38,Teams!$C:$C,Teams!$E:$E,,0,1) -> #VALUE! | L38: =RANDBETWEEN(90,120) -> 108 | M38: =_xlfn.XLOOKUP(I38,Teams!$C:$C,Teams!$E:$E,,0,1) -> #VALUE! | N38: =RANDBETWEEN(90,120) -> 114 | O38: =IF(L38>N38,G38,I38) -> Colorado State | P38: =_xlfn.XLOOKUP(O38,Teams!$C:$C,Teams!$E:$E,,0,1) -> #VALUE! | Q38: Lorem ipsum dolor sit amet, consectetur adipiscing elit, sed do eiusmod tempor incididunt ut labore et dolore magna aliqua. | R38: =IF( O38=G38, IF(F38>J38,TRUE,FALSE), IF(J38>F38,TRUE,FALSE)) -> TRUE
A39: =G39 -> Columbia | B39: =I39 -> Connecticut | C39: =IF(O39="","",IF(A39=O39,B39,A39)) -> Columbia | D39: =IF(SeedType=1,0,IF(SeedType=2,VLOOKUP(O39,SeedInfo,2,FALSE)*1,MAX(VLOOKUP(O39,SeedInfo,2,FALSE)-VLOOKUP(C39,SeedInfo,2,FALSE),0))) -> #REF! | E39: 30 | F39: {=_xlfn.XLOOKUP(G39,Teams[[#All],[Team]],Teams[[#All],[Seed]],0,0,1)} -> 3 | G39: =Teams!C60 -> Columbia | H39: vs | I39: =Teams!C61 -> Connecticut | J39: {=_xlfn.XLOOKUP(I39,Teams[[#All],[Team]],Teams[[#All],[Seed]],0,0,1)} -> 14 | K39: =_xlfn.XLOOKUP(G39,Teams!$C:$C,Teams!$E:$E,,0,1) -> #VALUE! | L39: =RANDBETWEEN(90,120) -> 108 | M39: =_xlfn.XLOOKUP(I39,Teams!$C:$C,Teams!$E:$E,,0,1) -> #VALUE! | N39: =RANDBETWEEN(90,120) -> 119 | O39: =IF(L39>N39,G39,I39) -> Connecticut | P39: =_xlfn.XLOOKUP(O39,Teams!$C:$C,Teams!$E:$E,,0,1) -> #VALUE! | Q39: Lorem ipsum dolor sit amet, consectetur adipiscing elit, sed do eiusmod tempor incididunt ut labore et dolore magna aliqua. | R39: =IF( O39=G39, IF(F39>J39,TRUE,FALSE), IF(J39>F39,TRUE,FALSE)) -> TRUE
A40: =G40 -> Coppin State | B40: =I40 -> Cornell | C40: =IF(O40="","",IF(A40=O40,B40,A40)) -> Cornell | D40: =IF(SeedType=1,0,IF(SeedType=2,VLOOKUP(O40,SeedInfo,2,FALSE)*1,MAX(VLOOKUP(O40,SeedInfo,2,FALSE)-VLOOKUP(C40,SeedInfo,2,FALSE),0))) -> #REF! | E40: 31 | F40: {=_xlfn.XLOOKUP(G40,Teams[[#All],[Team]],Teams[[#All],[Seed]],0,0,1)} -> 7 | G40: =Teams!C62 -> Coppin State | H40: vs | I40: =Teams!C63 -> Cornell | J40: {=_xlfn.XLOOKUP(I40,Teams[[#All],[Team]],Teams[[#All],[Seed]],0,0,1)} -> 10 | K40: =_xlfn.XLOOKUP(G40,Teams!$C:$C,Teams!$E:$E,,0,1) -> #VALUE! | L40: =RANDBETWEEN(90,120) -> 111 | M40: =_xlfn.XLOOKUP(I40,Teams!$C:$C,Teams!$E:$E,,0,1) -> #VALUE! | N40: =RANDBETWEEN(90,120) -> 100 | O40: =IF(L40>N40,G40,I40) -> Coppin State | P40: =_xlfn.XLOOKUP(O40,Teams!$C:$C,Teams!$E:$E,,0,1) -> #VALUE! | Q40: Lorem ipsum dolor sit amet, consectetur adipiscing elit, sed do eiusmod tempor incididunt ut labore et dolore magna aliqua. | R40: =IF( O40=G40, IF(F40>J40,TRUE,FALSE), IF(J40>F40,TRUE,FALSE)) -> FALSE
A41: =G41 -> Creighton | B41: =I41 -> Dartmouth | C41: =IF(O41="","",IF(A41=O41,B41,A41)) -> Dartmouth | D41: =IF(SeedType=1,0,IF(SeedType=2,VLOOKUP(O41,SeedInfo,2,FALSE)*1,MAX(VLOOKUP(O41,SeedInfo,2,FALSE)-VLOOKUP(C41,SeedInfo,2,FALSE),0))) -> #REF! | E41: 32 | F41: {=_xlfn.XLOOKUP(G41,Teams[[#All],[Team]],Teams[[#All],[Seed]],0,0,1)} -> 2 | G41: =Teams!C64 -> Creighton | H41: vs | I41: =Teams!C65 -> Dartmouth | J41: {=_xlfn.XLOOKUP(I41,Teams[[#All],[Team]],Teams[[#All],[Seed]],0,0,1)} -> 15 | K41: =_xlfn.XLOOKUP(G41,Teams!$C:$C,Teams!$E:$E,,0,1) -> #VALUE! | L41: =RANDBETWEEN(90,120) -> 120 | M41: =_xlfn.XLOOKUP(I41,Teams!$C:$C,Teams!$E:$E,,0,1) -> #VALUE! | N41: =RANDBETWEEN(90,120) -> 119 | O41: =IF(L41>N41,G41,I41) -> Creighton | P41: =_xlfn.XLOOKUP(O41,Teams!$C:$C,Teams!$E:$E,,0,1) -> #VALUE! | Q41: Lorem ipsum dolor sit amet, consectetur adipiscing elit, sed do eiusmod tempor incididunt ut labore et dolore magna aliqua. | R41: =IF( O41=G41, IF(F41>J41,TRUE,FALSE), IF(J41>F41,TRUE,FALSE)) -> FALSE
E42: Game # | F42: =Bracket!F2 -> Second Round | O42: Winner
...

Sheet Bracket
B1: 2026 NCAA Basketball Tournament Bracket
C2: First Round | F2: Second Round | I2: Sweet 16 | L2: Elite 8 | O2: Final Four | S2: Championship | AA2: Final Four | AD2: Elite 8 | AG2: Sweet 16 | AJ2: =F2 -> Second Round | AM2: =C2 -> First Round | AU2: checkbox
AU3: x
B5: 1 | C5: =Games!G10 -> Abilene Christian | D5: =_xlfn.XLOOKUP(C5,Teams!$C:$C,Teams!$E:$E,,0,1) -> #VALUE! | E5: =Games!L10 -> 115 | F5: =Games!O10 -> Abilene Christian | G5: =_xlfn.XLOOKUP(F5,Teams!$C:$C,Teams!$E:$E,,0,1) -> #VALUE! | H5: =Games!L43 -> 113 | AH5: =Games!L51 -> 93 | AI5: =_xlfn.XLOOKUP(AJ5,Teams!$C:$C,Teams!$E:$E,,0,1) -> #VALUE! | AJ5: =Games!O26 -> Bucknell | AK5: =Games!L26 -> 118 | AL5: =_xlfn.XLOOKUP(AM5,Teams!$C:$C,Teams!$E:$E,,0,1) -> #VALUE! | AM5: =Games!G26 -> Bucknell | AN5: 1 | AU5: =IF(AP29="x",TRUE,FALSE) -> TRUE
A6: =IF($AU$5=TRUE,1,"") -> 1 | AO6: =IF($AU$5=TRUE,A66+1,"") -> 17
B7: 16 | C7: =Games!I10 -> Air Force | D7: =_xlfn.XLOOKUP(C7,Teams!$C:$C,Teams!$E:$E,,0,1) -> #VALUE! | E7: =Games!N10 -> 111 | F7: =IF($AU$5=TRUE,AO66+1,"") -> 33 | I7: =Games!O43 -> Abilene Christian | J7: =_xlfn.XLOOKUP(I7,Teams!$C:$C,Teams!$E:$E,,0,1) -> #VALUE! | K7: =Games!L60 -> 107 | AE7: =Games!L64 -> 113 | AF7: =_xlfn.XLOOKUP(AG7,Teams!$C:$C,Teams!$E:$E,,0,1) -> #VALUE! | AG7: =Games!O51 -> Bucknell | AJ7: =IF($AU$5=TRUE,F63+1,"") -> 41 | AK7: =Games!N26 -> 98 | AL7: =_xlfn.XLOOKUP(AM7,Teams!$C:$C,Teams!$E:$E,,0,1) -> #VALUE! | AM7: =Games!I26 -> Buffalo | AN7: 16
B9: 8 | C9: =Games!G11 -> Akron | D9: =_xlfn.XLOOKUP(C9,Teams!$C:$C,Teams!$E:$E,,0,1) -> #VALUE! | E9: =Games!L11 -> 97 | F9: =Games!O11 -> Alabama | G9: =_xlfn.XLOOKUP(F9,Teams!$C:$C,Teams!$E:$E,,0,1) -> #VALUE! | H9: =Games!N43 -> 109 | AH9: =Games!N51 -> 90 | AI9: =_xlfn.XLOOKUP(AJ9,Teams!$C:$C,Teams!$E:$E,,0,1) -> #VALUE! | AJ9: =Games!O27 -> Butler | AK9: =Games!L27 -> 109 | AL9: =_xlfn.XLOOKUP(AM9,Teams!$C:$C,Teams!$E:$E,,0,1) -> #VALUE! | AM9: =Games!G27 -> Butler | AN9: 8
A10: =IF($AU$5=TRUE,A6+1,"") -> 2 | AO10: =IF($AU$5=TRUE,AO6+1,"") -> 18
B11: 9 | C11: =Games!I11 -> Alabama | D11: =_xlfn.XLOOKUP(C11,Teams!$C:$C,Teams!$E:$E,,0,1) -> #VALUE! | E11: =Games!N11 -> 120 | I11: =IF($AU$5=TRUE,AJ63+1,"") -> 49 | L11: =Games!O60 -> Abilene Christian | M11: =_xlfn.XLOOKUP(L11,Teams!$C:$C,Teams!$E:$E,,0,1) -> #VALUE! | N11: =Games!L69 -> 90 | T11: =_xlfn.XLOOKUP(S32,Teams!$C:$C,Teams!$E:$E,,0,1) -> #VALUE! | AB11: =Games!L71 -> 113 | AC11: =_xlfn.XLOOKUP(AD11,Teams!$C:$C,Teams!$E:$E,,0,1) -> #VALUE! | AD11: =Games!O64 -> Bucknell | AG11: =IF($AU$5=TRUE,I59+1,"") -> 53 | AK11: =Games!N27 -> 92 | AL11: =_xlfn.XLOOKUP(AM11,Teams!$C:$C,Teams!$E:$E,,0,1) -> #VALUE! | AM11: =Games!I27 -> Cal Poly | AN11: 9
B13: 5 | C13: =Games!G12 -> Alabama A&M | D13: =_xlfn.XLOOKUP(C13,Teams!$C:$C,Teams!$E:$E,,0,1) -> #VALUE! | E13: =Games!L12 -> 95 | F13: =Games!O12 -> Arizona | G13: =_xlfn.XLOOKUP(F13,Teams!$C:$C,Teams!$E:$E,,0,1) -> #VALUE! | H13: =Games!L44 -> 107 | AH13: =Games!L52 -> 98 | AI13: =_xlfn.XLOOKUP(AJ13,Teams!$C:$C,Teams!$E:$E,,0,1) -> #VALUE! | AJ13: =Games!O28 -> Cal State Fullerton | AK13: =Games!L28 -> 91 | AL13: =_xlfn.XLOOKUP(AM13,Teams!$C:$C,Teams!$E:$E,,0,1) -> #VALUE! | AM13: =Games!G28 -> Cal State Bakersfield | AN13: 5
A14: =IF($AU$5=TRUE,A10+1,"") -> 3 | AO14: =IF($AU$5=TRUE,AO10+1,"") -> 19
B15: 12 | C15: =Games!I12 -> Arizona | D15: =_xlfn.XLOOKUP(C15,Teams!$C:$C,Teams!$E:$E,,0,1) -> #VALUE! | E15: =Games!N12 -> 120 | F15: =IF($AU$5=TRUE,F7+1,"") -> 34 | I15: =Games!O44 -> Alcorn State | J15: =_xlfn.XLOOKUP(I15,Teams!$C:$C,Teams!$E:$E,,0,1) -> #VALUE! | K15: =Games!N60 -> 101 | AE15: =Games!N64 -> 93 | AF15: =_xlfn.XLOOKUP(AG15,Teams!$C:$C,Teams!$E:$E,,0,1) -> #VALUE! | AG15: =Games!O52 -> Cal State Northridge | AJ15: =IF($AU$5=TRUE,AJ7+1,"") -> 42 | AK15: =Games!N28 -> 100 | AL15: =_xlfn.XLOOKUP(AM15,Teams!$C:$C,Teams!$E:$E,,0,1) -> #VALUE! | AM15: =Games!I28 -> Cal State Fullerton | AN15: 12
B17: 4 | C17: =Games!G13 -> Arizona State | D17: =_xlfn.XLOOKUP(C17,Teams!$C:$C,Teams!$E:$E,,0,1) -> #VALUE! | E17: =Games!L13 -> 103 | F17: =Games!O13 -> Alcorn State | G17: =_xlfn.XLOOKUP(F17,Teams!$C:$C,Teams!$E:$E,,0,1) -> #VALUE! | H17: =Games!N44 -> 119 | AH17: =Games!N52 -> 109 | AI17: =_xlfn.XLOOKUP(AJ17,Teams!$C:$C,Teams!$E:$E,,0,1) -> #VALUE! | AJ17: =Games!O29 -> Cal State Northridge | AK17: =Games!L29 -> 116 | AL17: =_xlfn.XLOOKUP(AM17,Teams!$C:$C,Teams!$E:$E,,0,1) -> #VALUE! | AM17: =Games!G29 -> Cal State Northridge | AN17: 4
A18: =IF($AU$5=TRUE,A14+1,"") -> 4 | AO18: =IF($AU$5=TRUE,AO14+1,"") -> 20
B19: 13 | C19: =Games!I13 -> Alcorn State | D19: =_xlfn.XLOOKUP(C19,Teams!$C:$C,Teams!$E:$E,,0,1) -> #VALUE! | E19: =Games!N13 -> 112 | K19: South | O19: =Games!O69 -> Arizona State | P19: =_xlfn.XLOOKUP(O19,Teams!$C:$C,Teams!$E:$E,,0,1) -> #VALUE! | Q19: =Games!L74 -> 96 | Y19: =Games!L75 -> 98 | Z19: =_xlfn.XLOOKUP(AA19,Teams!$C:$C,Teams!$E:$E,,0,1) -> #VALUE! | AA19: =Games!O71 -> Bucknell | AD19: East | AK19: =Games!N29 -> 115 | AL19: =_xlfn.XLOOKUP(AM19,Teams!$C:$C,Teams!$E:$E,,0,1) -> #VALUE! | AM19: =Games!I29 -> California | AN19: 13
A21: =IF($AU$5=TRUE,A18+1,"") -> 5 | B21: 6 | C21: =Games!G14 -> American | D21: =_xlfn.XLOOKUP(C21,Teams!$C:$C,Teams!$E:$E,,0,1) -> #VALUE! | E21: =Games!L14 -> 106 | F21: =Games!O14 -> Appalachian State | G21: =_xlfn.XLOOKUP(F21,Teams!$C:$C,Teams!$E:$E,,0,1) -> #VALUE! | H21: =Games!L45 -> 102 | L21: =IF($AU$5=TRUE,AG59+1,"") -> 57 | AD21: =IF($AU$5=TRUE,L53+1,"") -> 59 | AH21: =Games!L53 -> 102 | AI21: =_xlfn.XLOOKUP(AJ21,Teams!$C:$C,Teams!$E:$E,,0,1) -> #VALUE! | AJ21: =Games!O30 -> California Baptist | AK21: =Games!L30 -> 108 | AL21: =_xlfn.XLOOKUP(AM21,Teams!$C:$C,Teams!$E:$E,,0,1) -> #VALUE! | AM21: =Games!G30 -> California Baptist | AN21: 6
AO22: =IF($AU$5=TRUE,AO18+1,"") -> 21
B23: 11 | C23: =Games!I14 -> Appalachian State | D23: =_xlfn.XLOOKUP(C23,Teams!$C:$C,Teams!$E:$E,,0,1) -> #VALUE! | E23: =Games!N14 -> 120 | F23: =IF($AU$5=TRUE,F15+1,"") -> 35 | I23: =Games!O45 -> Arizona State | J23: =_xlfn.XLOOKUP(I23,Teams!$C:$C,Teams!$E:$E,,0,1) -> #VALUE! | K23: =Games!L61 -> 115 | AE23: =Games!L65 -> 91 | AF23: =_xlfn.XLOOKUP(AG23,Teams!$C:$C,Teams!$E:$E,,0,1) -> #VALUE! | AG23: =Games!O53 -> Central Arkansas | AJ23: =IF($AU$5=TRUE,AJ15+1,"") -> 43 | AK23: =Games!N30 -> 94 | AL23: =_xlfn.XLOOKUP(AM23,Teams!$C:$C,Teams!$E:$E,,0,1) -> #VALUE! | AM23: =Games!I30 -> Campbell | AN23: 11
B25: 3 | C25: =Games!G15 -> Arizona | D25: =_xlfn.XLOOKUP(C25,Teams!$C:$C,Teams!$E:$E,,0,1) -> #VALUE! | E25: =Games!L15 -> 95 | F25: =Games!O15 -> Arizona State | G25: =_xlfn.XLOOKUP(F25,Teams!$C:$C,Teams!$E:$E,,0,1) -> #VALUE! | H25: =Games!N45 -> 114 | AH25: =Games!N53 -> 107 | AI25: =_xlfn.XLOOKUP(AJ25,Teams!$C:$C,Teams!$E:$E,,0,1) -> #VALUE! | AJ25: =Games!O31 -> Central Arkansas | AK25: =Games!L31 -> 104 | AL25: =_xlfn.XLOOKUP(AM25,Teams!$C:$C,Teams!$E:$E,,0,1) -> #VALUE! | AM25: =Games!G31 -> Canisius | AN25: 3
A26: =IF($AU$5=TRUE,A21+1,"") -> 6 | AO26: =IF($AU$5=TRUE,AO22+1,"") -> 22
B27: 14 | C27: =Games!I15 -> Arizona State | D27: =_xlfn.XLOOKUP(C27,Teams!$C:$C,Teams!$E:$E,,0,1) -> #VALUE! | E27: =Games!N15 -> 115 | I27: =IF($AU$5=TRUE,I11+1,"") -> 50 | L27: =Games!O61 -> Arizona State | M27: =_xlfn.XLOOKUP(L27,Teams!$C:$C,Teams!$E:$E,,0,1) -> #VALUE! | N27: =Games!N69 -> 117 | R27: =Games!O74 -> Baylor | U27: =_xlfn.XLOOKUP(R27,Teams!$C:$C,Teams!$E:$E,,0,1) -> #VALUE! | V27: =Games!L77 -> 100 | AB27: =Games!N71 -> 112 | AC27: =_xlfn.XLOOKUP(AD27,Teams!$C:$C,Teams!$E:$E,,0,1) -> #VALUE! | AD27: =Games!O65 -> Charlotte | AG27: =IF($AU$5=TRUE,AG11+1,"") -> 54 | AK27: =Games!N31 -> 116 | AL27: =_xlfn.XLOOKUP(AM27,Teams!$C:$C,Teams!$E:$E,,0,1) -> #VALUE! | AM27: =Games!I31 -> Central Arkansas | AN27: 14
B29: 7 | C29: =Games!G16 -> Arkansas | D29: =_xlfn.XLOOKUP(C29,Teams!$C:$C,Teams!$E:$E,,0,1) -> #VALUE! | E29: =Games!L16 -> 117 | F29: =Games!O16 -> Arkansas | G29: =_xlfn.XLOOKUP(F29,Teams!$C:$C,Teams!$E:$E,,0,1) -> #VALUE! | H29: =Games!L46 -> 91 | AH29: =Games!L54 -> 105 | AI29: =_xlfn.XLOOKUP(AJ29,Teams!$C:$C,Teams!$E:$E,,0,1) -> #VALUE! | AJ29: =Games!O32 -> Central Michigan | AK29: =Games!L32 -> 91 | AL29: =_xlfn.XLOOKUP(AM29,Teams!$C:$C,Teams!$E:$E,,0,1) -> #VALUE! | AM29: =Games!G32 -> Central Connecticut State | AN29: 7 | AP29: x | AQ29: Show Game Numbers
A30: =IF($AU$5=TRUE,A26+1,"") -> 7 | AO30: =IF($AU$5=TRUE,AO26+1,"") -> 23
